Workbook

Sheet Editable assumptions
A1: Editable assumptions
A2: AgentBisect — Financial Model · Main Scenario
A4: Variable / dimension | B4: Value
A5: Model cost per investigation | B5: =0.25 -> 0.25
A6: Compute cost per investigation | B6: =0.05 -> 0.05
A7: Compute minutes per investigation | B7: =10 -> 10
A8: Fixed hosting | B8: =300 -> 300
A9: Founder monthly salary | B9: =8000 -> 8000
A10: Unpaid founder months | B10: =6 -> 6
A11: Starting cash | B11: =25000 -> 25000
A12: Opening paying teams | B12: =0 -> 0
A13: Net new teams per month | B13: =5 -> 5
A14: Free repos | B14: =50 -> 50
A15: Forecast months | B15: =24 -> 24
A16: Forecast start | B16: =DATE(2026,10,1) -> 46296
A17: Month 12 paying team target | B17: ='Editable assumptions'!B12+'Editable assumptions'!B13*12 -> 60

Sheet Unit economics by plan
A1: Unit economics by plan
A2: AgentBisect — Financial Model · Main Scenario
A4: Variable / dimension | B4: Monthly price per repo | C4: Included investigations | D4: Average investigations | E4: Overage price | F4: Revenue per repo | G4: Investigation unit cost | H4: Variable cost per repo | I4: Contribution per repo | J4: Contribution margin | K4: Compute hours per repo
A5: Free | B5: =0 -> 0 | C5: =10 -> 10 | D5: =10 -> 10 | E5: =0 -> 0 | F5: ='Unit economics by plan'!B5+MAX('Unit economics by plan'!D5-'Unit economics by plan'!C5,0)*'Unit economics by plan'!E5 -> 0 | G5: ='Editable assumptions'!B5+'Editable assumptions'!B6 -> 0.3 | H5: ='Unit economics by plan'!D5*'Unit economics by plan'!G5 -> 3 | I5: ='Unit economics by plan'!F5-'Unit economics by plan'!H5 -> -3 | J5: =IFERROR('Unit economics by plan'!I5/'Unit economics by plan'!F5,"") | K5: ='Unit economics by plan'!D5*'Editable assumptions'!B7/60 -> 1.6666667
A6: Team | B6: =99 -> 99 | C6: =100 -> 100 | D6: =60 -> 60 | E6: =1 -> 1 | F6: ='Unit economics by plan'!B6+MAX('Unit economics by plan'!D6-'Unit economics by plan'!C6,0)*'Unit economics by plan'!E6 -> 99 | G6: ='Editable assumptions'!B5+'Editable assumptions'!B6 -> 0.3 | H6: ='Unit economics by plan'!D6*'Unit economics by plan'!G6 -> 18 | I6: ='Unit economics by plan'!F6-'Unit economics by plan'!H6 -> 81 | J6: =IFERROR('Unit economics by plan'!I6/'Unit economics by plan'!F6,"") -> 0.81818182 | K6: ='Unit economics by plan'!D6*'Editable assumptions'!B7/60 -> 10

Sheet Monthly forecast and cash
A1: Monthly forecast and cash
A2: AgentBisect — Financial Model · Main Scenario
A4: Variable / dimension | B4: 2026-09 | C4: 2026-10 | D4: 2026-11 | E4: 2026-12 | F4: 2027-01 | G4: 2027-02 | H4: 2027-03 | I4: 2027-04 | J4: 2027-05 | K4: 2027-06 | L4: 2027-07 | M4: 2027-08 | N4: 2027-09 | O4: 2027-10 | P4: 2027-11 | Q4: 2027-12 | R4: 2028-01 | S4: 2028-02 | T4: 2028-03 | U4: 2028-04 | V4: 2028-05 | W4: 2028-06 | X4: 2028-07 | Y4: 2028-08 | Z4: 2028-09
A5: Forecast month number | B5: 0 | C5: =DATEDIF('Editable assumptions'!B16,DATE(2026,10,1),"M")+1 -> 1 | D5: =DATEDIF('Editable assumptions'!B16,DATE(2026,11,1),"M")+1 -> 2 | E5: =DATEDIF('Editable assumptions'!B16,DATE(2026,12,1),"M")+1 -> 3 | F5: =DATEDIF('Editable assumptions'!B16,DATE(2027,1,1),"M")+1 -> 4 | G5: =DATEDIF('Editable assumptions'!B16,DATE(2027,2,1),"M")+1 -> 5 | H5: =DATEDIF('Editable assumptions'!B16,DATE(2027,3,1),"M")+1 -> 6 | I5: =DATEDIF('Editable assumptions'!B16,DATE(2027,4,1),"M")+1 -> 7 | J5: =DATEDIF('Editable assumptions'!B16,DATE(2027,5,1),"M")+1 -> 8 | K5: =DATEDIF('Editable assumptions'!B16,DATE(2027,6,1),"M")+1 -> 9 | L5: =DATEDIF('Editable assumptions'!B16,DATE(2027,7,1),"M")+1 -> 10 | M5: =DATEDIF('Editable assumptions'!B16,DATE(2027,8,1),"M")+1 -> 11 | N5: =DATEDIF('Editable assumptions'!B16,DATE(2027,9,1),"M")+1 -> 12 | O5: =DATEDIF('Editable assumptions'!B16,DATE(2027,10,1),"M")+1 -> 13 | P5: =DATEDIF('Editable assumptions'!B16,DATE(2027,11,1),"M")+1 -> 14 | Q5: =DATEDIF('Editable assumptions'!B16,DATE(2027,12,1),"M")+1 -> 15 | R5: =DATEDIF('Editable assumptions'!B16,DATE(2028,1,1),"M")+1 -> 16 | S5: =DATEDIF('Editable assumptions'!B16,DATE(2028,2,1),"M")+1 -> 17 | T5: =DATEDIF('Editable assumptions'!B16,DATE(2028,3,1),"M")+1 -> 18 | U5: =DATEDIF('Editable assumptions'!B16,DATE(2028,4,1),"M")+1 -> 19 | V5: =DATEDIF('Editable assumptions'!B16,DATE(2028,5,1),"M")+1 -> 20 | W5: =DATEDIF('Editable assumptions'!B16,DATE(2028,6,1),"M")+1 -> 21 | X5: =DATEDIF('Editable assumptions'!B16,DATE(2028,7,1),"M")+1 -> 22 | Y5: =DATEDIF('Editable assumptions'!B16,DATE(2028,8,1),"M")+1 -> 23 | Z5: =DATEDIF('Editable assumptions'!B16,DATE(2028,9,1),"M")+1 -> 24
A6: Monthly net new teams | B6: 0 | C6: =IF('Editable assumptions'!B13="","",'Editable assumptions'!B13) -> 5 | D6: =IF('Monthly forecast and cash'!C6="","",'Monthly forecast and cash'!C6) -> 5 | E6: =IF('Monthly forecast and cash'!D6="","",'Monthly forecast and cash'!D6) -> 5 | F6: =IF('Monthly forecast and cash'!E6="","",'Monthly forecast and cash'!E6) -> 5 | G6: =IF('Monthly forecast and cash'!F6="","",'Monthly forecast and cash'!F6) -> 5 | H6: =IF('Monthly forecast and cash'!G6="","",'Monthly forecast and cash'!G6) -> 5 | I6: =IF('Monthly forecast and cash'!H6="","",'Monthly forecast and cash'!H6) -> 5 | J6: =IF('Monthly forecast and cash'!I6="","",'Monthly forecast and cash'!I6) -> 5 | K6: =IF('Monthly forecast and cash'!J6="","",'Monthly forecast and cash'!J6) -> 5 | ... Z6: =IF('Monthly forecast and cash'!Y6="","",'Monthly forecast and cash'!Y6) -> 5
A7: Paying teams | B7: 0 | C7: =IF(IF(IF(IF(ISERROR('Monthly forecast and cash'!C5=1),'Monthly forecast and cash'!C5=1,IF('Monthly forecast and cash'!C5="","",'Monthly forecast and cash'!C5=1))="",FALSE,IF(ISERROR('Monthly forecast and cash'!C5=1),'Monthly forecast and cash'!C5=1,IF('Monthly forecast and cash'!C5="","",'Monthly forecast and cash'!C5=1))),IF('Editable assumptions'!B12="","",'Editable assumptions'!B12),IF('Monthly forecast and cash'!B7="","",'Monthly forecast and cash'!B7))="",0,IF(IF(IF(ISERROR('Monthly forecast and cash'!C5=1),'Monthly forecast and cash'!C5=1,IF('Monthly forecast and cash'!C5="","",'Monthly forecast and cash'!C5=1))="",FALSE,IF(ISERROR('Monthly forecast and cash'!C5=1),'Monthly forecast and cash'!C5=1,IF('Monthly forecast and cash'!C5="","",'Monthly forecast and cash'!C5=1))),IF('Editable assumptions'!B12="","",'Editable assumptions'!B12),IF('Monthly forecast and cash'!B7="","",'Monthly forecast and cash'!B7)))+'Monthly forecast and cash'!C6 -> 5 | D7: =IF(IF(IF(IF(ISERROR('Monthly forecast and cash'!D5=1),'Monthly forecast and cash'!D5=1,IF('Monthly forecast and cash'!D5="","",'Monthly forecast and cash'!D5=1))="",FALSE,IF(ISERROR('Monthly forecast and cash'!D5=1),'Monthly forecast and cash'!D5=1,IF('Monthly forecast and cash'!D5="","",'Monthly forecast and cash'!D5=1))),IF('Editable assumptions'!B12="","",'Editable assumptions'!B12),IF('Monthly forecast and cash'!C7="","",'Monthly forecast and cash'!C7))="",0,IF(IF(IF(ISERROR('Monthly forecast and cash'!D5=1),'Monthly forecast and cash'!D5=1,IF('Monthly forecast and cash'!D5="","",'Monthly forecast and cash'!D5=1))="",FALSE,IF(ISERROR('Monthly forecast and cash'!D5=1),'Monthly forecast and cash'!D5=1,IF('Monthly forecast and cash'!D5="","",'Monthly forecast and cash'!D5=1))),IF('Editable assumptions'!B12="","",'Editable assumptions'!B12),IF('Monthly forecast and cash'!C7="","",'Monthly forecast and cash'!C7)))+'Monthly forecast and cash'!D6 -> 10 | E7: =IF(IF(IF(IF(ISERROR('Monthly forecast and cash'!E5=1),'Monthly forecast and cash'!E5=1,IF('Monthly forecast and cash'!E5="","",'Monthly forecast and cash'!E5=1))="",FALSE,IF(ISERROR('Monthly forecast and cash'!E5=1),'Monthly forecast and cash'!E5=1,IF('Monthly forecast and cash'!E5="","",'Monthly forecast and cash'!E5=1))),IF('Editable assumptions'!B12="","",'Editable assumptions'!B12),IF('Monthly forecast and cash'!D7="","",'Monthly forecast and cash'!D7))="",0,IF(IF(IF(ISERROR('Monthly forecast and cash'!E5=1),'Monthly forecast and cash'!E5=1,IF('Monthly forecast and cash'!E5="","",'Monthly forecast and cash'!E5=1))="",FALSE,IF(ISERROR('Monthly forecast and cash'!E5=1),'Monthly forecast and cash'!E5=1,IF('Monthly forecast and cash'!E5="","",'Monthly forecast and cash'!E5=1))),IF('Editable assumptions'!B12="","",'Editable assumptions'!B12),IF('Monthly forecast and cash'!D7="","",'Monthly forecast and cash'!D7)))+'Monthly forecast and cash'!E6 -> 15 | F7: =IF(IF(IF(IF(ISERROR('Monthly forecast and cash'!F5=1),'Monthly forecast and cash'!F5=1,IF('Monthly forecast and cash'!F5="","",'Monthly forecast and cash'!F5=1))="",FALSE,IF(ISERROR('Monthly forecast and cash'!F5=1),'Monthly forecast and cash'!F5=1,IF('Monthly forecast and cash'!F5="","",'Monthly forecast and cash'!F5=1))),IF('Editable assumptions'!B12="","",'Editable assumptions'!B12),IF('Monthly forecast and cash'!E7="","",'Monthly forecast and cash'!E7))="",0,IF(IF(IF(ISERROR('Monthly forecast and cash'!F5=1),'Monthly forecast and cash'!F5=1,IF('Monthly forecast and cash'!F5="","",'Monthly forecast and cash'!F5=1))="",FALSE,IF(ISERROR('Monthly forecast and cash'!F5=1),'Monthly forecast and cash'!F5=1,IF('Monthly forecast and cash'!F5="","",'Monthly forecast and cash'!F5=1))),IF('Editable assumptions'!B12="","",'Editable assumptions'!B12),IF('Monthly forecast and cash'!E7="","",'Monthly forecast and cash'!E7)))+'Monthly forecast and cash'!F6 -> 20 | G7: =IF(IF(IF(IF(ISERROR('Monthly forecast and cash'!G5=1),'Monthly forecast and cash'!G5=1,IF('Monthly forecast and cash'!G5="","",'Monthly forecast and cash'!G5=1))="",FALSE,IF(ISERROR('Monthly forecast and cash'!G5=1),'Monthly forecast and cash'!G5=1,IF('Monthly forecast and cash'!G5="","",'Monthly forecast and cash'!G5=1))),IF('Editable assumptions'!B12="","",'Editable assumptions'!B12),IF('Monthly forecast and cash'!F7="","",'Monthly forecast and cash'!F7))="",0,IF(IF(IF(ISERROR('Monthly forecast and cash'!G5=1),'Monthly forecast and cash'!G5=1,IF('Monthly forecast and cash'!G5="","",'Monthly forecast and cash'!G5=1))="",FALSE,IF(ISERROR('Monthly forecast and cash'!G5=1),'Monthly forecast and cash'!G5=1,IF('Monthly forecast and cash'!G5="","",'Monthly forecast and cash'!G5=1))),IF('Editable assumptions'!B12="","",'Editable assumptions'!B12),IF('Monthly forecast and cash'!F7="","",'Monthly forecast and cash'!F7)))+'Monthly forecast and cash'!G6 -> 25 | H7: =IF(IF(IF(IF(ISERROR('Monthly forecast and cash'!H5=1),'Monthly forecast and cash'!H5=1,IF('Monthly forecast and cash'!H5="","",'Monthly forecast and cash'!H5=1))="",FALSE,IF(ISERROR('Monthly forecast and cash'!H5=1),'Monthly forecast and cash'!H5=1,IF('Monthly forecast and cash'!H5="","",'Monthly forecast and cash'!H5=1))),IF('Editable assumptions'!B12="","",'Editable assumptions'!B12),IF('Monthly forecast and cash'!G7="","",'Monthly forecast and cash'!G7))="",0,IF(IF(IF(ISERROR('Monthly forecast and cash'!H5=1),'Monthly forecast and cash'!H5=1,IF('Monthly forecast and cash'!H5="","",'Monthly forecast and cash'!H5=1))="",FALSE,IF(ISERROR('Monthly forecast and cash'!H5=1),'Monthly forecast and cash'!H5=1,IF('Monthly forecast and cash'!H5="","",'Monthly forecast and cash'!H5=1))),IF('Editable assumptions'!B12="","",'Editable assumptions'!B12),IF('Monthly forecast and cash'!G7="","",'Monthly forecast and cash'!G7)))+'Monthly forecast and cash'!H6 -> 30 | I7: =IF(IF(IF(IF(ISERROR('Monthly forecast and cash'!I5=1),'Monthly forecast and cash'!I5=1,IF('Monthly forecast and cash'!I5="","",'Monthly forecast and cash'!I5=1))="",FALSE,IF(ISERROR('Monthly forecast and cash'!I5=1),'Monthly forecast and cash'!I5=1,IF('Monthly forecast and cash'!I5="","",'Monthly forecast and cash'!I5=1))),IF('Editable assumptions'!B12="","",'Editable assumptions'!B12),IF('Monthly forecast and cash'!H7="","",'Monthly forecast and cash'!H7))="",0,IF(IF(IF(ISERROR('Monthly forecast and cash'!I5=1),'Monthly forecast and cash'!I5=1,IF('Monthly forecast and cash'!I5="","",'Monthly forecast and cash'!I5=1))="",FALSE,IF(ISERROR('Monthly forecast and cash'!I5=1),'Monthly forecast and cash'!I5=1,IF('Monthly forecast and cash'!I5="","",'Monthly forecast and cash'!I5=1))),IF('Editable assumptions'!B12="","",'Editable assumptions'!B12),IF('Monthly forecast and cash'!H7="","",'Monthly forecast and cash'!H7)))+'Monthly forecast and cash'!I6 -> 35 | J7: =IF(IF(IF(IF(ISERROR('Monthly forecast and cash'!J5=1),'Monthly forecast and cash'!J5=1,IF('Monthly forecast and cash'!J5="","",'Monthly forecast and cash'!J5=1))="",FALSE,IF(ISERROR('Monthly forecast and cash'!J5=1),'Monthly forecast and cash'!J5=1,IF('Monthly forecast and cash'!J5="","",'Monthly forecast and cash'!J5=1))),IF('Editable assumptions'!B12="","",'Editable assumptions'!B12),IF('Monthly forecast and cash'!I7="","",'Monthly forecast and cash'!I7))="",0,IF(IF(IF(ISERROR('Monthly forecast and cash'!J5=1),'Monthly forecast and cash'!J5=1,IF('Monthly forecast and cash'!J5="","",'Monthly forecast and cash'!J5=1))="",FALSE,IF(ISERROR('Monthly forecast and cash'!J5=1),'Monthly forecast and cash'!J5=1,IF('Monthly forecast and cash'!J5="","",'Monthly forecast and cash'!J5=1))),IF('Editable assumptions'!B12="","",'Editable assumptions'!B12),IF('Monthly forecast and cash'!I7="","",'Monthly forecast and cash'!I7)))+'Monthly forecast and cash'!J6 -> 40 | K7: =IF(IF(IF(IF(ISERROR('Monthly forecast and cash'!K5=1),'Monthly forecast and cash'!K5=1,IF('Monthly forecast and cash'!K5="","",'Monthly forecast and cash'!K5=1))="",FALSE,IF(ISERROR('Monthly forecast and cash'!K5=1),'Monthly forecast and cash'!K5=1,IF('Monthly forecast and cash'!K5="","",'Monthly forecast and cash'!K5=1))),IF('Editable assumptions'!B12="","",'Editable assumptions'!B12),IF('Monthly forecast and cash'!J7="","",'Monthly forecast and cash'!J7))="",0,IF(IF(IF(ISERROR('Monthly forecast and cash'!K5=1),'Monthly forecast and cash'!K5=1,IF('Monthly forecast and cash'!K5="","",'Monthly forecast and cash'!K5=1))="",FALSE,IF(ISERROR('Monthly forecast and cash'!K5=1),'Monthly forecast and cash'!K5=1,IF('Monthly forecast and cash'!K5="","",'Monthly forecast and cash'!K5=1))),IF('Editable assumptions'!B12="","",'Editable assumptions'!B12),IF('Monthly forecast and cash'!J7="","",'Monthly forecast and cash'!J7)))+'Monthly forecast and cash'!K6 -> 45 | L7: =IF(IF(IF(IF(ISERROR('Monthly forecast and cash'!L5=1),'Monthly forecast and cash'!L5=1,IF('Monthly forecast and cash'!L5="","",'Monthly forecast and cash'!L5=1))="",FALSE,IF(ISERROR('Monthly forecast and cash'!L5=1),'Monthly forecast and cash'!L5=1,IF('Monthly forecast and cash'!L5="","",'Monthly forecast and cash'!L5=1))),IF('Editable assumptions'!B12="","",'Editable assumptions'!B12),IF('Monthly forecast and cash'!K7="","",'Monthly forecast and cash'!K7))="",0,IF(IF(IF(ISERROR('Monthly forecast and cash'!L5=1),'Monthly forecast and cash'!L5=1,IF('Monthly forecast and cash'!L5="","",'Monthly forecast and cash'!L5=1))="",FALSE,IF(ISERROR('Monthly forecast and cash'!L5=1),'Monthly forecast and cash'!L5=1,IF('Monthly forecast and cash'!L5="","",'Monthly forecast and cash'!L5=1))),IF('Editable assumptions'!B12="","",'Editable assumptions'!B12),IF('Monthly forecast and cash'!K7="","",'Monthly forecast and cash'!K7)))+'Monthly forecast and cash'!L6 -> 50 | M7: =IF(IF(IF(IF(ISERROR('Monthly forecast and cash'!M5=1),'Monthly forecast and cash'!M5=1,IF('Monthly forecast and cash'!M5="","",'Monthly forecast and cash'!M5=1))="",FALSE,IF(ISERROR('Monthly forecast and cash'!M5=1),'Monthly forecast and cash'!M5=1,IF('Monthly forecast and cash'!M5="","",'Monthly forecast and cash'!M5=1))),IF('Editable assumptions'!B12="","",'Editable assumptions'!B12),IF('Monthly forecast and cash'!L7="","",'Monthly forecast and cash'!L7))="",0,IF(IF(IF(ISERROR('Monthly forecast and cash'!M5=1),'Monthly forecast and cash'!M5=1,IF('Monthly forecast and cash'!M5="","",'Monthly forecast and cash'!M5=1))="",FALSE,IF(ISERROR('Monthly forecast and cash'!M5=1),'Monthly forecast and cash'!M5=1,IF('Monthly forecast and cash'!M5="","",'Monthly forecast and cash'!M5=1))),IF('Editable assumptions'!B12="","",'Editable assumptions'!B12),IF('Monthly forecast and cash'!L7="","",'Monthly forecast and cash'!L7)))+'Monthly forecast and cash'!M6 -> 55 | N7: =IF(IF(IF(IF(ISERROR('Monthly forecast and cash'!N5=1),'Monthly forecast and cash'!N5=1,IF('Monthly forecast and cash'!N5="","",'Monthly forecast and cash'!N5=1))="",FALSE,IF(ISERROR('Monthly forecast and cash'!N5=1),'Monthly forecast and cash'!N5=1,IF('Monthly forecast and cash'!N5="","",'Monthly forecast and cash'!N5=1))),IF('Editable assumptions'!B12="","",'Editable assumptions'!B12),IF('Monthly forecast and cash'!M7="","",'Monthly forecast and cash'!M7))="",0,IF(IF(IF(ISERROR('Monthly forecast and cash'!N5=1),'Monthly forecast and cash'!N5=1,IF('Monthly forecast and cash'!N5="","",'Monthly forecast and cash'!N5=1))="",FALSE,IF(ISERROR('Monthly forecast and cash'!N5=1),'Monthly forecast and cash'!N5=1,IF('Monthly forecast and cash'!N5="","",'Monthly forecast and cash'!N5=1))),IF('Editable assumptions'!B12="","",'Editable assumptions'!B12),IF('Monthly forecast and cash'!M7="","",'Monthly forecast and cash'!M7)))+'Monthly forecast and cash'!N6 -> 60 | O7: =IF(IF(IF(IF(ISERROR('Monthly forecast and cash'!O5=1),'Monthly forecast and cash'!O5=1,IF('Monthly forecast and cash'!O5="","",'Monthly forecast and cash'!O5=1))="",FALSE,IF(ISERROR('Monthly forecast and cash'!O5=1),'Monthly forecast and cash'!O5=1,IF('Monthly forecast and cash'!O5="","",'Monthly forecast and cash'!O5=1))),IF('Editable assumptions'!B12="","",'Editable assumptions'!B12),IF('Monthly forecast and cash'!N7="","",'Monthly forecast and cash'!N7))="",0,IF(IF(IF(ISERROR('Monthly forecast and cash'!O5=1),'Monthly forecast and cash'!O5=1,IF('Monthly forecast and cash'!O5="","",'Monthly forecast and cash'!O5=1))="",FALSE,IF(ISERROR('Monthly forecast and cash'!O5=1),'Monthly forecast and cash'!O5=1,IF('Monthly forecast and cash'!O5="","",'Monthly forecast and cash'!O5=1))),IF('Editable assumptions'!B12="","",'Editable assumptions'!B12),IF('Monthly forecast and cash'!N7="","",'Monthly forecast and cash'!N7)))+'Monthly forecast and cash'!O6 -> 65 | P7: =IF(IF(IF(IF(ISERROR('Monthly forecast and cash'!P5=1),'Monthly forecast and cash'!P5=1,IF('Monthly forecast and cash'!P5="","",'Monthly forecast and cash'!P5=1))="",FALSE,IF(ISERROR('Monthly forecast and cash'!P5=1),'Monthly forecast and cash'!P5=1,IF('Monthly forecast and cash'!P5="","",'Monthly forecast and cash'!P5=1))),IF('Editable assumptions'!B12="","",'Editable assumptions'!B12),IF('Monthly forecast and cash'!O7="","",'Monthly forecast and cash'!O7))="",0,IF(IF(IF(ISERROR('Monthly forecast and cash'!P5=1),'Monthly forecast and cash'!P5=1,IF('Monthly forecast and cash'!P5="","",'Monthly forecast and cash'!P5=1))="",FALSE,IF(ISERROR('Monthly forecast and cash'!P5=1),'Monthly forecast and cash'!P5=1,IF('Monthly forecast and cash'!P5="","",'Monthly forecast and cash'!P5=1))),IF('Editable assumptions'!B12="","",'Editable assumptions'!B12),IF('Monthly forecast and cash'!O7="","",'Monthly forecast and cash'!O7)))+'Monthly forecast and cash'!P6 -> 70 | Q7: =IF(IF(IF(IF(ISERROR('Monthly forecast and cash'!Q5=1),'Monthly forecast and cash'!Q5=1,IF('Monthly forecast and cash'!Q5="","",'Monthly forecast and cash'!Q5=1))="",FALSE,IF(ISERROR('Monthly forecast and cash'!Q5=1),'Monthly forecast and cash'!Q5=1,IF('Monthly forecast and cash'!Q5="","",'Monthly forecast and cash'!Q5=1))),IF('Editable assumptions'!B12="","",'Editable assumptions'!B12),IF('Monthly forecast and cash'!P7="","",'Monthly forecast and cash'!P7))="",0,IF(IF(IF(ISERROR('Monthly forecast and cash'!Q5=1),'Monthly forecast and cash'!Q5=1,IF('Monthly forecast and cash'!Q5="","",'Monthly forecast and cash'!Q5=1))="",FALSE,IF(ISERROR('Monthly forecast and cash'!Q5=1),'Monthly forecast and cash'!Q5=1,IF('Monthly forecast and cash'!Q5="","",'Monthly forecast and cash'!Q5=1))),IF('Editable assumptions'!B12="","",'Editable assumptions'!B12),IF('Monthly forecast and cash'!P7="","",'Monthly forecast and cash'!P7)))+'Monthly forecast and cash'!Q6 -> 75 | R7: =IF(IF(IF(IF(ISERROR('Monthly forecast and cash'!R5=1),'Monthly forecast and cash'!R5=1,IF('Monthly forecast and cash'!R5="","",'Monthly forecast and cash'!R5=1))="",FALSE,IF(ISERROR('Monthly forecast and cash'!R5=1),'Monthly forecast and cash'!R5=1,IF('Monthly forecast and cash'!R5="","",'Monthly forecast and cash'!R5=1))),IF('Editable assumptions'!B12="","",'Editable assumptions'!B12),IF('Monthly forecast and cash'!Q7="","",'Monthly forecast and cash'!Q7))="",0,IF(IF(IF(ISERROR('Monthly forecast and cash'!R5=1),'Monthly forecast and cash'!R5=1,IF('Monthly forecast and cash'!R5="","",'Monthly forecast and cash'!R5=1))="",FALSE,IF(ISERROR('Monthly forecast and cash'!R5=1),'Monthly forecast and cash'!R5=1,IF('Monthly forecast and cash'!R5="","",'Monthly forecast and cash'!R5=1))),IF('Editable assumptions'!B12="","",'Editable assumptions'!B12),IF('Monthly forecast and cash'!Q7="","",'Monthly forecast and cash'!Q7)))+'Monthly forecast and cash'!R6 -> 80 | S7: =IF(IF(IF(IF(ISERROR('Monthly forecast and cash'!S5=1),'Monthly forecast and cash'!S5=1,IF('Monthly forecast and cash'!S5="","",'Monthly forecast and cash'!S5=1))="",FALSE,IF(ISERROR('Monthly forecast and cash'!S5=1),'Monthly forecast and cash'!S5=1,IF('Monthly forecast and cash'!S5="","",'Monthly forecast and cash'!S5=1))),IF('Editable assumptions'!B12="","",'Editable assumptions'!B12),IF('Monthly forecast and cash'!R7="","",'Monthly forecast and cash'!R7))="",0,IF(IF(IF(ISERROR('Monthly forecast and cash'!S5=1),'Monthly forecast and cash'!S5=1,IF('Monthly forecast and cash'!S5="","",'Monthly forecast and cash'!S5=1))="",FALSE,IF(ISERROR('Monthly forecast and cash'!S5=1),'Monthly forecast and cash'!S5=1,IF('Monthly forecast and cash'!S5="","",'Monthly forecast and cash'!S5=1))),IF('Editable assumptions'!B12="","",'Editable assumptions'!B12),IF('Monthly forecast and cash'!R7="","",'Monthly forecast and cash'!R7)))+'Monthly forecast and cash'!S6 -> 85 | T7: =IF(IF(IF(IF(ISERROR('Monthly forecast and cash'!T5=1),'Monthly forecast and cash'!T5=1,IF('Monthly forecast and cash'!T5="","",'Monthly forecast and cash'!T5=1))="",FALSE,IF(ISERROR('Monthly forecast and cash'!T5=1),'Monthly forecast and cash'!T5=1,IF('Monthly forecast and cash'!T5="","",'Monthly forecast and cash'!T5=1))),IF('Editable assumptions'!B12="","",'Editable assumptions'!B12),IF('Monthly forecast and cash'!S7="","",'Monthly forecast and cash'!S7))="",0,IF(IF(IF(ISERROR('Monthly forecast and cash'!T5=1),'Monthly forecast and cash'!T5=1,IF('Monthly forecast and cash'!T5="","",'Monthly forecast and cash'!T5=1))="",FALSE,IF(ISERROR('Monthly forecast and cash'!T5=1),'Monthly forecast and cash'!T5=1,IF('Monthly forecast and cash'!T5="","",'Monthly forecast and cash'!T5=1))),IF('Editable assumptions'!B12="","",'Editable assumptions'!B12),IF('Monthly forecast and cash'!S7="","",'Monthly forecast and cash'!S7)))+'Monthly forecast and cash'!T6 -> 90 | U7: =IF(IF(IF(IF(ISERROR('Monthly forecast and cash'!U5=1),'Monthly forecast and cash'!U5=1,IF('Monthly forecast and cash'!U5="","",'Monthly forecast and cash'!U5=1))="",FALSE,IF(ISERROR('Monthly forecast and cash'!U5=1),'Monthly forecast and cash'!U5=1,IF('Monthly forecast and cash'!U5="","",'Monthly forecast and cash'!U5=1))),IF('Editable assumptions'!B12="","",'Editable assumptions'!B12),IF('Monthly forecast and cash'!T7="","",'Monthly forecast and cash'!T7))="",0,IF(IF(IF(ISERROR('Monthly forecast and cash'!U5=1),'Monthly forecast and cash'!U5=1,IF('Monthly forecast and cash'!U5="","",'Monthly forecast and cash'!U5=1))="",FALSE,IF(ISERROR('Monthly forecast and cash'!U5=1),'Monthly forecast and cash'!U5=1,IF('Monthly forecast and cash'!U5="","",'Monthly forecast and cash'!U5=1))),IF('Editable assumptions'!B12="","",'Editable assumptions'!B12),IF('Monthly forecast and cash'!T7="","",'Monthly forecast and cash'!T7)))+'Monthly forecast and cash'!U6 -> 95 | V7: =IF(IF(IF(IF(ISERROR('Monthly forecast and cash'!V5=1),'Monthly forecast and cash'!V5=1,IF('Monthly forecast and cash'!V5="","",'Monthly forecast and cash'!V5=1))="",FALSE,IF(ISERROR('Monthly forecast and cash'!V5=1),'Monthly forecast and cash'!V5=1,IF('Monthly forecast and cash'!V5="","",'Monthly forecast and cash'!V5=1))),IF('Editable assumptions'!B12="","",'Editable assumptions'!B12),IF('Monthly forecast and cash'!U7="","",'Monthly forecast and cash'!U7))="",0,IF(IF(IF(ISERROR('Monthly forecast and cash'!V5=1),'Monthly forecast and cash'!V5=1,IF('Monthly forecast and cash'!V5="","",'Monthly forecast and cash'!V5=1))="",FALSE,IF(ISERROR('Monthly forecast and cash'!V5=1),'Monthly forecast and cash'!V5=1,IF('Monthly forecast and cash'!V5="","",'Monthly forecast and cash'!V5=1))),IF('Editable assumptions'!B12="","",'Editable assumptions'!B12),IF('Monthly forecast and cash'!U7="","",'Monthly forecast and cash'!U7)))+'Monthly forecast and cash'!V6 -> 100 | W7: =IF(IF(IF(IF(ISERROR('Monthly forecast and cash'!W5=1),'Monthly forecast and cash'!W5=1,IF('Monthly forecast and cash'!W5="","",'Monthly forecast and cash'!W5=1))="",FALSE,IF(ISERROR('Monthly forecast and cash'!W5=1),'Monthly forecast and cash'!W5=1,IF('Monthly forecast and cash'!W5="","",'Monthly forecast and cash'!W5=1))),IF('Editable assumptions'!B12="","",'Editable assumptions'!B12),IF('Monthly forecast and cash'!V7="","",'Monthly forecast and cash'!V7))="",0,IF(IF(IF(ISERROR('Monthly forecast and cash'!W5=1),'Monthly forecast and cash'!W5=1,IF('Monthly forecast and cash'!W5="","",'Monthly forecast and cash'!W5=1))="",FALSE,IF(ISERROR('Monthly forecast and cash'!W5=1),'Monthly forecast and cash'!W5=1,IF('Monthly forecast and cash'!W5="","",'Monthly forecast and cash'!W5=1))),IF('Editable assumptions'!B12="","",'Editable assumptions'!B12),IF('Monthly forecast and cash'!V7="","",'Monthly forecast and cash'!V7)))+'Monthly forecast and cash'!W6 -> 105 | X7: =IF(IF(IF(IF(ISERROR('Monthly forecast and cash'!X5=1),'Monthly forecast and cash'!X5=1,IF('Monthly forecast and cash'!X5="","",'Monthly forecast and cash'!X5=1))="",FALSE,IF(ISERROR('Monthly forecast and cash'!X5=1),'Monthly forecast and cash'!X5=1,IF('Monthly forecast and cash'!X5="","",'Monthly forecast and cash'!X5=1))),IF('Editable assumptions'!B12="","",'Editable assumptions'!B12),IF('Monthly forecast and cash'!W7="","",'Monthly forecast and cash'!W7))="",0,IF(IF(IF(ISERROR('Monthly forecast and cash'!X5=1),'Monthly forecast and cash'!X5=1,IF('Monthly forecast and cash'!X5="","",'Monthly forecast and cash'!X5=1))="",FALSE,IF(ISERROR('Monthly forecast and cash'!X5=1),'Monthly forecast and cash'!X5=1,IF('Monthly forecast and cash'!X5="","",'Monthly forecast and cash'!X5=1))),IF('Editable assumptions'!B12="","",'Editable assumptions'!B12),IF('Monthly forecast and cash'!W7="","",'Monthly forecast and cash'!W7)))+'Monthly forecast and cash'!X6 -> 110 | Y7: =IF(IF(IF(IF(ISERROR('Monthly forecast and cash'!Y5=1),'Monthly forecast and cash'!Y5=1,IF('Monthly forecast and cash'!Y5="","",'Monthly forecast and cash'!Y5=1))="",FALSE,IF(ISERROR('Monthly forecast and cash'!Y5=1),'Monthly forecast and cash'!Y5=1,IF('Monthly forecast and cash'!Y5="","",'Monthly forecast and cash'!Y5=1))),IF('Editable assumptions'!B12="","",'Editable assumptions'!B12),IF('Monthly forecast and cash'!X7="","",'Monthly forecast and cash'!X7))="",0,IF(IF(IF(ISERROR('Monthly forecast and cash'!Y5=1),'Monthly forecast and cash'!Y5=1,IF('Monthly forecast and cash'!Y5="","",'Monthly forecast and cash'!Y5=1))="",FALSE,IF(ISERROR('Monthly forecast and cash'!Y5=1),'Monthly forecast and cash'!Y5=1,IF('Monthly forecast and cash'!Y5="","",'Monthly forecast and cash'!Y5=1))),IF('Editable assumptions'!B12="","",'Editable assumptions'!B12),IF('Monthly forecast and cash'!X7="","",'Monthly forecast and cash'!X7)))+'Monthly forecast and cash'!Y6 -> 115 | Z7: =IF(IF(IF(IF(ISERROR('Monthly forecast and cash'!Z5=1),'Monthly forecast and cash'!Z5=1,IF('Monthly forecast and cash'!Z5="","",'Monthly forecast and cash'!Z5=1))="",FALSE,IF(ISERROR('Monthly forecast and cash'!Z5=1),'Monthly forecast and cash'!Z5=1,IF('Monthly forecast and cash'!Z5="","",'Monthly forecast and cash'!Z5=1))),IF('Editable assumptions'!B12="","",'Editable assumptions'!B12),IF('Monthly forecast and cash'!Y7="","",'Monthly forecast and cash'!Y7))="",0,IF(IF(IF(ISERROR('Monthly forecast and cash'!Z5=1),'Monthly forecast and cash'!Z5=1,IF('Monthly forecast and cash'!Z5="","",'Monthly forecast and cash'!Z5=1))="",FALSE,IF(ISERROR('Monthly forecast and cash'!Z5=1),'Monthly forecast and cash'!Z5=1,IF('Monthly forecast and cash'!Z5="","",'Monthly forecast and cash'!Z5=1))),IF('Editable assumptions'!B12="","",'Editable assumptions'!B12),IF('Monthly forecast and cash'!Y7="","",'Monthly forecast and cash'!Y7)))+'Monthly forecast and cash'!Z6 -> 120
A8: Active free repos | B8: 0 | C8: =IF('Editable assumptions'!B14="","",'Editable assumptions'!B14) -> 50 | D8: =IF('Editable assumptions'!B14="","",'Editable assumptions'!B14) -> 50 | E8: =IF('Editable assumptions'!B14="","",'Editable assumptions'!B14) -> 50 | F8: =IF('Editable assumptions'!B14="","",'Editable assumptions'!B14) -> 50 | G8: =IF('Editable assumptions'!B14="","",'Editable assumptions'!B14) -> 50 | H8: =IF('Editable assumptions'!B14="","",'Editable assumptions'!B14) -> 50 | I8: =IF('Editable assumptions'!B14="","",'Editable assumptions'!B14) -> 50 | J8: =IF('Editable assumptions'!B14="","",'Editable assumptions'!B14) -> 50 | K8: =IF('Editable assumptions'!B14="","",'Editable assumptions'!B14) -> 50 | L8: =IF('Editable assumptions'!B14="","",'Editable assumptions'!B14) -> 50 | M8: =IF('Editable assumptions'!B14="","",'Editable assumptions'!B14) -> 50 | N8: =IF('Editable assumptions'!B14="","",'Editable assumptions'!B14) -> 50 | O8: =IF('Editable assumptions'!B14="","",'Editable assumptions'!B14) -> 50 | P8: =IF('Editable assumptions'!B14="","",'Editable assumptions'!B14) -> 50 | Q8: =IF('Editable assumptions'!B14="","",'Editable assumptions'!B14) -> 50 | R8: =IF('Editable assumptions'!B14="","",'Editable assumptions'!B14) -> 50 | S8: =IF('Editable assumptions'!B14="","",'Editable assumptions'!B14) -> 50 | T8: =IF('Editable assumptions'!B14="","",'Editable assumptions'!B14) -> 50 | U8: =IF('Editable assumptions'!B14="","",'Editable assumptions'!B14) -> 50 | V8: =IF('Editable assumptions'!B14="","",'Editable assumptions'!B14) -> 50 | W8: =IF('Editable assumptions'!B14="","",'Editable assumptions'!B14) -> 50 | X8: =IF('Editable assumptions'!B14="","",'Editable assumptions'!B14) -> 50 | Y8: =IF('Editable assumptions'!B14="","",'Editable assumptions'!B14) -> 50 | Z8: =IF('Editable assumptions'!B14="","",'Editable assumptions'!B14) -> 50
A9: Investigations | B9: =SUM('Monthly forecast and cash'!B10,'Monthly forecast and cash'!B11) -> 0 | C9: =SUM('Monthly forecast and cash'!C10,'Monthly forecast and cash'!C11) -> 800 | D9: =SUM('Monthly forecast and cash'!D10,'Monthly forecast and cash'!D11) -> 1100 | E9: =SUM('Monthly forecast and cash'!E10,'Monthly forecast and cash'!E11) -> 1400 | F9: =SUM('Monthly forecast and cash'!F10,'Monthly forecast and cash'!F11) -> 1700 | G9: =SUM('Monthly forecast and cash'!G10,'Monthly forecast and cash'!G11) -> 2000 | H9: =SUM('Monthly forecast and cash'!H10,'Monthly forecast and cash'!H11) -> 2300 | I9: =SUM('Monthly forecast and cash'!I10,'Monthly forecast and cash'!I11) -> 2600 | ... Z9: =SUM('Monthly forecast and cash'!Z10,'Monthly forecast and cash'!Z11) -> 7700
A10: Free | B10: =0 -> 0 | C10: =IF(IF(EXACT("Free","Team"),IF('Monthly forecast and cash'!C7="","",'Monthly forecast and cash'!C7),IF('Monthly forecast and cash'!C8="","",'Monthly forecast and cash'!C8))="",0,IF(EXACT("Free","Team"),IF('Monthly forecast and cash'!C7="","",'Monthly forecast and cash'!C7),IF('Monthly forecast and cash'!C8="","",'Monthly forecast and cash'!C8)))*'Unit economics by plan'!D5 -> 500 | D10: =IF(IF(EXACT("Free","Team"),IF('Monthly forecast and cash'!D7="","",'Monthly forecast and cash'!D7),IF('Monthly forecast and cash'!D8="","",'Monthly forecast and cash'!D8))="",0,IF(EXACT("Free","Team"),IF('Monthly forecast and cash'!D7="","",'Monthly forecast and cash'!D7),IF('Monthly forecast and cash'!D8="","",'Monthly forecast and cash'!D8)))*'Unit economics by plan'!D5 -> 500 | E10: =IF(IF(EXACT("Free","Team"),IF('Monthly forecast and cash'!E7="","",'Monthly forecast and cash'!E7),IF('Monthly forecast and cash'!E8="","",'Monthly forecast and cash'!E8))="",0,IF(EXACT("Free","Team"),IF('Monthly forecast and cash'!E7="","",'Monthly forecast and cash'!E7),IF('Monthly forecast and cash'!E8="","",'Monthly forecast and cash'!E8)))*'Unit economics by plan'!D5 -> 500 | F10: =IF(IF(EXACT("Free","Team"),IF('Monthly forecast and cash'!F7="","",'Monthly forecast and cash'!F7),IF('Monthly forecast and cash'!F8="","",'Monthly forecast and cash'!F8))="",0,IF(EXACT("Free","Team"),IF('Monthly forecast and cash'!F7="","",'Monthly forecast and cash'!F7),IF('Monthly forecast and cash'!F8="","",'Monthly forecast and cash'!F8)))*'Unit economics by plan'!D5 -> 500 | G10: =IF(IF(EXACT("Free","Team"),IF('Monthly forecast and cash'!G7="","",'Monthly forecast and cash'!G7),IF('Monthly forecast and cash'!G8="","",'Monthly forecast and cash'!G8))="",0,IF(EXACT("Free","Team"),IF('Monthly forecast and cash'!G7="","",'Monthly forecast and cash'!G7),IF('Monthly forecast and cash'!G8="","",'Monthly forecast and cash'!G8)))*'Unit economics by plan'!D5 -> 500 | H10: =IF(IF(EXACT("Free","Team"),IF('Monthly forecast and cash'!H7="","",'Monthly forecast and cash'!H7),IF('Monthly forecast and cash'!H8="","",'Monthly forecast and cash'!H8))="",0,IF(EXACT("Free","Team"),IF('Monthly forecast and cash'!H7="","",'Monthly forecast and cash'!H7),IF('Monthly forecast and cash'!H8="","",'Monthly forecast and cash'!H8)))*'Unit economics by plan'!D5 -> 500 | I10: =IF(IF(EXACT("Free","Team"),IF('Monthly forecast and cash'!I7="","",'Monthly forecast and cash'!I7),IF('Monthly forecast and cash'!I8="","",'Monthly forecast and cash'!I8))="",0,IF(EXACT("Free","Team"),IF('Monthly forecast and cash'!I7="","",'Monthly forecast and cash'!I7),IF('Monthly forecast and cash'!I8="","",'Monthly forecast and cash'!I8)))*'Unit economics by plan'!D5 -> 500 | J10: =IF(IF(EXACT("Free","Team"),IF('Monthly forecast and cash'!J7="","",'Monthly forecast and cash'!J7),IF('Monthly forecast and cash'!J8="","",'Monthly forecast and cash'!J8))="",0,IF(EXACT("Free","Team"),IF('Monthly forecast and cash'!J7="","",'Monthly forecast and cash'!J7),IF('Monthly forecast and cash'!J8="","",'Monthly forecast and cash'!J8)))*'Unit economics by plan'!D5 -> 500 | K10: =IF(IF(EXACT("Free","Team"),IF('Monthly forecast and cash'!K7="","",'Monthly forecast and cash'!K7),IF('Monthly forecast and cash'!K8="","",'Monthly forecast and cash'!K8))="",0,IF(EXACT("Free","Team"),IF('Monthly forecast and cash'!K7="","",'Monthly forecast and cash'!K7),IF('Monthly forecast and cash'!K8="","",'Monthly forecast and cash'!K8)))*'Unit economics by plan'!D5 -> 500 | L10: =IF(IF(EXACT("Free","Team"),IF('Monthly forecast and cash'!L7="","",'Monthly forecast and cash'!L7),IF('Monthly forecast and cash'!L8="","",'Monthly forecast and cash'!L8))="",0,IF(EXACT("Free","Team"),IF('Monthly forecast and cash'!L7="","",'Monthly forecast and cash'!L7),IF('Monthly forecast and cash'!L8="","",'Monthly forecast and cash'!L8)))*'Unit economics by plan'!D5 -> 500 | M10: =IF(IF(EXACT("Free","Team"),IF('Monthly forecast and cash'!M7="","",'Monthly forecast and cash'!M7),IF('Monthly forecast and cash'!M8="","",'Monthly forecast and cash'!M8))="",0,IF(EXACT("Free","Team"),IF('Monthly forecast and cash'!M7="","",'Monthly forecast and cash'!M7),IF('Monthly forecast and cash'!M8="","",'Monthly forecast and cash'!M8)))*'Unit economics by plan'!D5 -> 500 | N10: =IF(IF(EXACT("Free","Team"),IF('Monthly forecast and cash'!N7="","",'Monthly forecast and cash'!N7),IF('Monthly forecast and cash'!N8="","",'Monthly forecast and cash'!N8))="",0,IF(EXACT("Free","Team"),IF('Monthly forecast and cash'!N7="","",'Monthly forecast and cash'!N7),IF('Monthly forecast and cash'!N8="","",'Monthly forecast and cash'!N8)))*'Unit economics by plan'!D5 -> 500 | O10: =IF(IF(EXACT("Free","Team"),IF('Monthly forecast and cash'!O7="","",'Monthly forecast and cash'!O7),IF('Monthly forecast and cash'!O8="","",'Monthly forecast and cash'!O8))="",0,IF(EXACT("Free","Team"),IF('Monthly forecast and cash'!O7="","",'Monthly forecast and cash'!O7),IF('Monthly forecast and cash'!O8="","",'Monthly forecast and cash'!O8)))*'Unit economics by plan'!D5 -> 500 | P10: =IF(IF(EXACT("Free","Team"),IF('Monthly forecast and cash'!P7="","",'Monthly forecast and cash'!P7),IF('Monthly forecast and cash'!P8="","",'Monthly forecast and cash'!P8))="",0,IF(EXACT("Free","Team"),IF('Monthly forecast and cash'!P7="","",'Monthly forecast and cash'!P7),IF('Monthly forecast and cash'!P8="","",'Monthly forecast and cash'!P8)))*'Unit economics by plan'!D5 -> 500 | Q10: =IF(IF(EXACT("Free","Team"),IF('Monthly forecast and cash'!Q7="","",'Monthly forecast and cash'!Q7),IF('Monthly forecast and cash'!Q8="","",'Monthly forecast and cash'!Q8))="",0,IF(EXACT("Free","Team"),IF('Monthly forecast and cash'!Q7="","",'Monthly forecast and cash'!Q7),IF('Monthly forecast and cash'!Q8="","",'Monthly forecast and cash'!Q8)))*'Unit economics by plan'!D5 -> 500 | R10: =IF(IF(EXACT("Free","Team"),IF('Monthly forecast and cash'!R7="","",'Monthly forecast and cash'!R7),IF('Monthly forecast and cash'!R8="","",'Monthly forecast and cash'!R8))="",0,IF(EXACT("Free","Team"),IF('Monthly forecast and cash'!R7="","",'Monthly forecast and cash'!R7),IF('Monthly forecast and cash'!R8="","",'Monthly forecast and cash'!R8)))*'Unit economics by plan'!D5 -> 500 | S10: =IF(IF(EXACT("Free","Team"),IF('Monthly forecast and cash'!S7="","",'Monthly forecast and cash'!S7),IF('Monthly forecast and cash'!S8="","",'Monthly forecast and cash'!S8))="",0,IF(EXACT("Free","Team"),IF('Monthly forecast and cash'!S7="","",'Monthly forecast and cash'!S7),IF('Monthly forecast and cash'!S8="","",'Monthly forecast and cash'!S8)))*'Unit economics by plan'!D5 -> 500 | T10: =IF(IF(EXACT("Free","Team"),IF('Monthly forecast and cash'!T7="","",'Monthly forecast and cash'!T7),IF('Monthly forecast and cash'!T8="","",'Monthly forecast and cash'!T8))="",0,IF(EXACT("Free","Team"),IF('Monthly forecast and cash'!T7="","",'Monthly forecast and cash'!T7),IF('Monthly forecast and cash'!T8="","",'Monthly forecast and cash'!T8)))*'Unit economics by plan'!D5 -> 500 | U10: =IF(IF(EXACT("Free","Team"),IF('Monthly forecast and cash'!U7="","",'Monthly forecast and cash'!U7),IF('Monthly forecast and cash'!U8="","",'Monthly forecast and cash'!U8))="",0,IF(EXACT("Free","Team"),IF('Monthly forecast and cash'!U7="","",'Monthly forecast and cash'!U7),IF('Monthly forecast and cash'!U8="","",'Monthly forecast and cash'!U8)))*'Unit economics by plan'!D5 -> 500 | V10: =IF(IF(EXACT("Free","Team"),IF('Monthly forecast and cash'!V7="","",'Monthly forecast and cash'!V7),IF('Monthly forecast and cash'!V8="","",'Monthly forecast and cash'!V8))="",0,IF(EXACT("Free","Team"),IF('Monthly forecast and cash'!V7="","",'Monthly forecast and cash'!V7),IF('Monthly forecast and cash'!V8="","",'Monthly forecast and cash'!V8)))*'Unit economics by plan'!D5 -> 500 | W10: =IF(IF(EXACT("Free","Team"),IF('Monthly forecast and cash'!W7="","",'Monthly forecast and cash'!W7),IF('Monthly forecast and cash'!W8="","",'Monthly forecast and cash'!W8))="",0,IF(EXACT("Free","Team"),IF('Monthly forecast and cash'!W7="","",'Monthly forecast and cash'!W7),IF('Monthly forecast and cash'!W8="","",'Monthly forecast and cash'!W8)))*'Unit economics by plan'!D5 -> 500 | X10: =IF(IF(EXACT("Free","Team"),IF('Monthly forecast and cash'!X7="","",'Monthly forecast and cash'!X7),IF('Monthly forecast and cash'!X8="","",'Monthly forecast and cash'!X8))="",0,IF(EXACT("Free","Team"),IF('Monthly forecast and cash'!X7="","",'Monthly forecast and cash'!X7),IF('Monthly forecast and cash'!X8="","",'Monthly forecast and cash'!X8)))*'Unit economics by plan'!D5 -> 500 | Y10: =IF(IF(EXACT("Free","Team"),IF('Monthly forecast and cash'!Y7="","",'Monthly forecast and cash'!Y7),IF('Monthly forecast and cash'!Y8="","",'Monthly forecast and cash'!Y8))="",0,IF(EXACT("Free","Team"),IF('Monthly forecast and cash'!Y7="","",'Monthly forecast and cash'!Y7),IF('Monthly forecast and cash'!Y8="","",'Monthly forecast and cash'!Y8)))*'Unit economics by plan'!D5 -> 500 | Z10: =IF(IF(EXACT("Free","Team"),IF('Monthly forecast and cash'!Z7="","",'Monthly forecast and cash'!Z7),IF('Monthly forecast and cash'!Z8="","",'Monthly forecast and cash'!Z8))="",0,IF(EXACT("Free","Team"),IF('Monthly forecast and cash'!Z7="","",'Monthly forecast and cash'!Z7),IF('Monthly forecast and cash'!Z8="","",'Monthly forecast and cash'!Z8)))*'Unit economics by plan'!D5 -> 500
A11: Team | B11: =0 -> 0 | C11: =IF(IF(EXACT("Team","Team"),IF('Monthly forecast and cash'!C7="","",'Monthly forecast and cash'!C7),IF('Monthly forecast and cash'!C8="","",'Monthly forecast and cash'!C8))="",0,IF(EXACT("Team","Team"),IF('Monthly forecast and cash'!C7="","",'Monthly forecast and cash'!C7),IF('Monthly forecast and cash'!C8="","",'Monthly forecast and cash'!C8)))*'Unit economics by plan'!D6 -> 300 | D11: =IF(IF(EXACT("Team","Team"),IF('Monthly forecast and cash'!D7="","",'Monthly forecast and cash'!D7),IF('Monthly forecast and cash'!D8="","",'Monthly forecast and cash'!D8))="",0,IF(EXACT("Team","Team"),IF('Monthly forecast and cash'!D7="","",'Monthly forecast and cash'!D7),IF('Monthly forecast and cash'!D8="","",'Monthly forecast and cash'!D8)))*'Unit economics by plan'!D6 -> 600 | E11: =IF(IF(EXACT("Team","Team"),IF('Monthly forecast and cash'!E7="","",'Monthly forecast and cash'!E7),IF('Monthly forecast and cash'!E8="","",'Monthly forecast and cash'!E8))="",0,IF(EXACT("Team","Team"),IF('Monthly forecast and cash'!E7="","",'Monthly forecast and cash'!E7),IF('Monthly forecast and cash'!E8="","",'Monthly forecast and cash'!E8)))*'Unit economics by plan'!D6 -> 900 | F11: =IF(IF(EXACT("Team","Team"),IF('Monthly forecast and cash'!F7="","",'Monthly forecast and cash'!F7),IF('Monthly forecast and cash'!F8="","",'Monthly forecast and cash'!F8))="",0,IF(EXACT("Team","Team"),IF('Monthly forecast and cash'!F7="","",'Monthly forecast and cash'!F7),IF('Monthly forecast and cash'!F8="","",'Monthly forecast and cash'!F8)))*'Unit economics by plan'!D6 -> 1200 | G11: =IF(IF(EXACT("Team","Team"),IF('Monthly forecast and cash'!G7="","",'Monthly forecast and cash'!G7),IF('Monthly forecast and cash'!G8="","",'Monthly forecast and cash'!G8))="",0,IF(EXACT("Team","Team"),IF('Monthly forecast and cash'!G7="","",'Monthly forecast and cash'!G7),IF('Monthly forecast and cash'!G8="","",'Monthly forecast and cash'!G8)))*'Unit economics by plan'!D6 -> 1500 | H11: =IF(IF(EXACT("Team","Team"),IF('Monthly forecast and cash'!H7="","",'Monthly forecast and cash'!H7),IF('Monthly forecast and cash'!H8="","",'Monthly forecast and cash'!H8))="",0,IF(EXACT("Team","Team"),IF('Monthly forecast and cash'!H7="","",'Monthly forecast and cash'!H7),IF('Monthly forecast and cash'!H8="","",'Monthly forecast and cash'!H8)))*'Unit economics by plan'!D6 -> 1800 | I11: =IF(IF(EXACT("Team","Team"),IF('Monthly forecast and cash'!I7="","",'Monthly forecast and cash'!I7),IF('Monthly forecast and cash'!I8="","",'Monthly forecast and cash'!I8))="",0,IF(EXACT("Team","Team"),IF('Monthly forecast and cash'!I7="","",'Monthly forecast and cash'!I7),IF('Monthly forecast and cash'!I8="","",'Monthly forecast and cash'!I8)))*'Unit economics by plan'!D6 -> 2100 | J11: =IF(IF(EXACT("Team","Team"),IF('Monthly forecast and cash'!J7="","",'Monthly forecast and cash'!J7),IF('Monthly forecast and cash'!J8="","",'Monthly forecast and cash'!J8))="",0,IF(EXACT("Team","Team"),IF('Monthly forecast and cash'!J7="","",'Monthly forecast and cash'!J7),IF('Monthly forecast and cash'!J8="","",'Monthly forecast and cash'!J8)))*'Unit economics by plan'!D6 -> 2400 | K11: =IF(IF(EXACT("Team","Team"),IF('Monthly forecast and cash'!K7="","",'Monthly forecast and cash'!K7),IF('Monthly forecast and cash'!K8="","",'Monthly forecast and cash'!K8))="",0,IF(EXACT("Team","Team"),IF('Monthly forecast and cash'!K7="","",'Monthly forecast and cash'!K7),IF('Monthly forecast and cash'!K8="","",'Monthly forecast and cash'!K8)))*'Unit economics by plan'!D6 -> 2700 | L11: =IF(IF(EXACT("Team","Team"),IF('Monthly forecast and cash'!L7="","",'Monthly forecast and cash'!L7),IF('Monthly forecast and cash'!L8="","",'Monthly forecast and cash'!L8))="",0,IF(EXACT("Team","Team"),IF('Monthly forecast and cash'!L7="","",'Monthly forecast and cash'!L7),IF('Monthly forecast and cash'!L8="","",'Monthly forecast and cash'!L8)))*'Unit economics by plan'!D6 -> 3000 | M11: =IF(IF(EXACT("Team","Team"),IF('Monthly forecast and cash'!M7="","",'Monthly forecast and cash'!M7),IF('Monthly forecast and cash'!M8="","",'Monthly forecast and cash'!M8))="",0,IF(EXACT("Team","Team"),IF('Monthly forecast and cash'!M7="","",'Monthly forecast and cash'!M7),IF('Monthly forecast and cash'!M8="","",'Monthly forecast and cash'!M8)))*'Unit economics by plan'!D6 -> 3300 | N11: =IF(IF(EXACT("Team","Team"),IF('Monthly forecast and cash'!N7="","",'Monthly forecast and cash'!N7),IF('Monthly forecast and cash'!N8="","",'Monthly forecast and cash'!N8))="",0,IF(EXACT("Team","Team"),IF('Monthly forecast and cash'!N7="","",'Monthly forecast and cash'!N7),IF('Monthly forecast and cash'!N8="","",'Monthly forecast and cash'!N8)))*'Unit economics by plan'!D6 -> 3600 | O11: =IF(IF(EXACT("Team","Team"),IF('Monthly forecast and cash'!O7="","",'Monthly forecast and cash'!O7),IF('Monthly forecast and cash'!O8="","",'Monthly forecast and cash'!O8))="",0,IF(EXACT("Team","Team"),IF('Monthly forecast and cash'!O7="","",'Monthly forecast and cash'!O7),IF('Monthly forecast and cash'!O8="","",'Monthly forecast and cash'!O8)))*'Unit economics by plan'!D6 -> 3900 | P11: =IF(IF(EXACT("Team","Team"),IF('Monthly forecast and cash'!P7="","",'Monthly forecast and cash'!P7),IF('Monthly forecast and cash'!P8="","",'Monthly forecast and cash'!P8))="",0,IF(EXACT("Team","Team"),IF('Monthly forecast and cash'!P7="","",'Monthly forecast and cash'!P7),IF('Monthly forecast and cash'!P8="","",'Monthly forecast and cash'!P8)))*'Unit economics by plan'!D6 -> 4200 | Q11: =IF(IF(EXACT("Team","Team"),IF('Monthly forecast and cash'!Q7="","",'Monthly forecast and cash'!Q7),IF('Monthly forecast and cash'!Q8="","",'Monthly forecast and cash'!Q8))="",0,IF(EXACT("Team","Team"),IF('Monthly forecast and cash'!Q7="","",'Monthly forecast and cash'!Q7),IF('Monthly forecast and cash'!Q8="","",'Monthly forecast and cash'!Q8)))*'Unit economics by plan'!D6 -> 4500 | R11: =IF(IF(EXACT("Team","Team"),IF('Monthly forecast and cash'!R7="","",'Monthly forecast and cash'!R7),IF('Monthly forecast and cash'!R8="","",'Monthly forecast and cash'!R8))="",0,IF(EXACT("Team","Team"),IF('Monthly forecast and cash'!R7="","",'Monthly forecast and cash'!R7),IF('Monthly forecast and cash'!R8="","",'Monthly forecast and cash'!R8)))*'Unit economics by plan'!D6 -> 4800 | S11: =IF(IF(EXACT("Team","Team"),IF('Monthly forecast and cash'!S7="","",'Monthly forecast and cash'!S7),IF('Monthly forecast and cash'!S8="","",'Monthly forecast and cash'!S8))="",0,IF(EXACT("Team","Team"),IF('Monthly forecast and cash'!S7="","",'Monthly forecast and cash'!S7),IF('Monthly forecast and cash'!S8="","",'Monthly forecast and cash'!S8)))*'Unit economics by plan'!D6 -> 5100 | T11: =IF(IF(EXACT("Team","Team"),IF('Monthly forecast and cash'!T7="","",'Monthly forecast and cash'!T7),IF('Monthly forecast and cash'!T8="","",'Monthly forecast and cash'!T8))="",0,IF(EXACT("Team","Team"),IF('Monthly forecast and cash'!T7="","",'Monthly forecast and cash'!T7),IF('Monthly forecast and cash'!T8="","",'Monthly forecast and cash'!T8)))*'Unit economics by plan'!D6 -> 5400 | U11: =IF(IF(EXACT("Team","Team"),IF('Monthly forecast and cash'!U7="","",'Monthly forecast and cash'!U7),IF('Monthly forecast and cash'!U8="","",'Monthly forecast and cash'!U8))="",0,IF(EXACT("Team","Team"),IF('Monthly forecast and cash'!U7="","",'Monthly forecast and cash'!U7),IF('Monthly forecast and cash'!U8="","",'Monthly forecast and cash'!U8)))*'Unit economics by plan'!D6 -> 5700 | V11: =IF(IF(EXACT("Team","Team"),IF('Monthly forecast and cash'!V7="","",'Monthly forecast and cash'!V7),IF('Monthly forecast and cash'!V8="","",'Monthly forecast and cash'!V8))="",0,IF(EXACT("Team","Team"),IF('Monthly forecast and cash'!V7="","",'Monthly forecast and cash'!V7),IF('Monthly forecast and cash'!V8="","",'Monthly forecast and cash'!V8)))*'Unit economics by plan'!D6 -> 6000 | W11: =IF(IF(EXACT("Team","Team"),IF('Monthly forecast and cash'!W7="","",'Monthly forecast and cash'!W7),IF('Monthly forecast and cash'!W8="","",'Monthly forecast and cash'!W8))="",0,IF(EXACT("Team","Team"),IF('Monthly forecast and cash'!W7="","",'Monthly forecast and cash'!W7),IF('Monthly forecast and cash'!W8="","",'Monthly forecast and cash'!W8)))*'Unit economics by plan'!D6 -> 6300 | X11: =IF(IF(EXACT("Team","Team"),IF('Monthly forecast and cash'!X7="","",'Monthly forecast and cash'!X7),IF('Monthly forecast and cash'!X8="","",'Monthly forecast and cash'!X8))="",0,IF(EXACT("Team","Team"),IF('Monthly forecast and cash'!X7="","",'Monthly forecast and cash'!X7),IF('Monthly forecast and cash'!X8="","",'Monthly forecast and cash'!X8)))*'Unit economics by plan'!D6 -> 6600 | Y11: =IF(IF(EXACT("Team","Team"),IF('Monthly forecast and cash'!Y7="","",'Monthly forecast and cash'!Y7),IF('Monthly forecast and cash'!Y8="","",'Monthly forecast and cash'!Y8))="",0,IF(EXACT("Team","Team"),IF('Monthly forecast and cash'!Y7="","",'Monthly forecast and cash'!Y7),IF('Monthly forecast and cash'!Y8="","",'Monthly forecast and cash'!Y8)))*'Unit economics by plan'!D6 -> 6900 | Z11: =IF(IF(EXACT("Team","Team"),IF('Monthly forecast and cash'!Z7="","",'Monthly forecast and cash'!Z7),IF('Monthly forecast and cash'!Z8="","",'Monthly forecast and cash'!Z8))="",0,IF(EXACT("Team","Team"),IF('Monthly forecast and cash'!Z7="","",'Monthly forecast and cash'!Z7),IF('Monthly forecast and cash'!Z8="","",'Monthly forecast and cash'!Z8)))*'Unit economics by plan'!D6 -> 7200
A12: Revenue | B12: =SUM('Monthly forecast and cash'!B13,'Monthly forecast and cash'!B14) -> 0 | C12: =SUM('Monthly forecast and cash'!C13,'Monthly forecast and cash'!C14) -> 495 | D12: =SUM('Monthly forecast and cash'!D13,'Monthly forecast and cash'!D14) -> 990 | E12: =SUM('Monthly forecast and cash'!E13,'Monthly forecast and cash'!E14) -> 1485 | F12: =SUM('Monthly forecast and cash'!F13,'Monthly forecast and cash'!F14) -> 1980 | G12: =SUM('Monthly forecast and cash'!G13,'Monthly forecast and cash'!G14) -> 2475 | H12: =SUM('Monthly forecast and cash'!H13,'Monthly forecast and cash'!H14) -> 2970 | I12: =SUM('Monthly forecast and cash'!I13,'Monthly forecast and cash'!I14) -> 3465 | ... Z12: =SUM('Monthly forecast and cash'!Z13,'Monthly forecast and cash'!Z14) -> 11880
